Workbook

Sheet Нұсқау
A1: ЗЕРТТЕУ КЕСТЕСІН ТОЛТЫРУ НҰСҚАУЫ
A2: Сары ұяшықтарды ғана толтырыңыз. «Қорытынды» парағы өздігінен есептеледі.
A4: 1-КЕЗЕҢ. Мәтін талдауы
A5: 1. «Шығармалар» парағындағы 15 шығарманы оқыңыз. Қай кітаптан (баспасы, жылы) оқығаныңызды жазып, «Оқылды» бағанына «иә» деп белгілеңіз.
A6: 2. Шығармада ұлттық ойын кездессе, «Мәтін талдауы» парағына жаңа жол қосыңыз: бір эпизод – бір жол.
A7: 3. Ойынды тізімнен таңдаңыз. Тізімде жоқ болса, «Басқа» деп таңдап, атауын келесі бағанға жазыңыз.
A8: 4. Эпизодты 1–2 сөйлеммен өз сөзіңізбен жазыңыз және мәтіннен қысқа үзінді (дәйексөз) мен бетін көрсетіңіз.
A9: 5. Ойынның сюжеттегі негізгі қызметін бір кодпен белгілеңіз:
A10: С – Сынақ: Қаһарман ойын арқылы сыналады: қалыңдық, атақ немесе сенім үшін жарысады
A11: Б – Сюжетті бастау: Ойын кезіндегі оқиға кейіпкерді жолға шығарады немесе жаңа оқиғаны бастайды
A12: Қ – Қасиетін көрсету: Ойын кейіпкердің күшін, ептілігін, ақылын немесе тапқырлығын көрсетеді
A13: Т – Той-думан көрінісі: Ойын той, ас, мереке суретінің бөлігі ретінде сипатталады
... A19: 8. Әр ойын бойынша екі сұрақ: «Бұл ойынды білесің бе?» (0 – білмеймін, 1 – естігенмін, 2 – ойнағанмын/көргенмін) және «Ертегіден не жырдан оқыдың ба?» (1 – иә, 0 – жоқ).

Sheet Ойындар
A1: № | B1: Ойын | C1: Түрі | D1: Қысқаша ережесі
A2: 1 | B2: Бәйге | C2: Ат ойындары | D2: Ат жарысы. Аттар белгіленген жерден бірге шығып, мәреге бірінші жеткен ат жеңеді. Ұзақ қашықтыққа шабылатын түрі – аламан бәйге.
A3: 2 | B3: Көкпар | C3: Ат ойындары | D3: Шабандоздар ат үстінде серкенің немесе ешкінің тұлыбын бір-бірінен тартып алып, межелі жерге жеткізуге тырысады.
A4: 3 | B4: Қыз қуу | C4: Ат ойындары | D4: Жігіт атпен шауып, қызды қуып жетуі керек. Жете алмаса, кері қайтқанда қыз оны қамшымен қуады.
A5: 4 | B5: Теңге алу | C5: Ат ойындары | D5: Шабандоз шауып келе жатып, еңкейіп, жерде жатқан теңгені немесе орамалды іліп алады.
A6: 5 | B6: Аударыспақ | C6: Ат ойындары | D6: Ат үстіндегі екі балуан бір-бірін аттан аударып түсіруге тырысады.
A7: 6 | B7: Күрес | C7: Күш және мергендік ойындары | D7: Екі балуан белбеуден ұстап белдеседі. Қарсыласын жауырынымен жерге түсірген жеңеді.
A8: 7 | B8: Жамбы ату | C8: Күш және мергендік ойындары | D8: Мерген ат үстінде шауып келе жатып, биік ағашқа ілінген жамбыны (күміс құймасын) садақпен атып түсіреді.
A9: 8 | B9: Тоғызқұмалақ | C9: Зияткерлік және сөз ойындары | D9: Екі ойыншы ойнайды. Әрқайсысында 9 отау, әр отауда 9 құмалақтан болады. Құмалақтар отаулар бойынша таратылады, 81-ден көп құмалақ жинаған жеңеді.
A10: 9 | B10: Жұмбақ айтысу | C10: Зияткерлік және сөз ойындары | D10: Екі жақ бір-біріне кезекпен жұмбақ айтады. Жұмбақты шеше алмаған жақ жеңіледі.
A11: 10 | B11: Асық | C11: Балалар ойындары | D11: Асықтар қатарға тізіліп, ойыншылар оларды сақамен атып ұтып алады. Асықтың төрт жағы бар: алшы, тәйке, бүк, шік.
A12: 11 | B12: Ақсүйек | C12: Балалар ойындары | D12: Айлы түнде ойналады. Ақ сүйекті алысқа лақтырады, екі топ оны іздеп тауып, өз жағына жеткізуге тырысады.
A13: 12 | B13: Алтыбақан | C13: Ойын-сауық | D13: Алты ұзын ағаштан құрылған әткеншек. Кешке жастар жиналып, тербеліп, ән айтып, ойын-сауық құрады.
A14: 13 | B14: Басқа | C14: Басқа ойындар

Sheet Шығармалар
A1: № | B1: Шығарма | C1: Жанры | D1: басылым,сілтеме (кітап, баспа, жылы) | E1: Оқылды (иә/жоқ)
A2: 1 | B2: Ер Төстік | C2: Ертегі | D2: Ер Төстік [Мәтін] : қазақтың көне ертегілері (жаңартылған нұсқа) / М. Байбеков О. Байбеков ... – Тараз : Сенім, 2019 | E2: иә
A3: 2 | B3: Керқұла атты Кендебай | C3: Ертегі | D3: https://adebiportal.kz/kz/balaqai/view/kerqula-atty-kendebai__126 | E3: иә
A4: 3 | B4: Алтын сақа | C4: Ертегі | D4: Алтын сақа – Алматы, 1972. | E4: иә
A5: 4 | B5: Күн астындағы Күнікей қыз | C5: Ертегі | D5: https://bilim-all.kz/article/263 | E5: иә
A6: 5 | B6: Алпамыс батыр | C6: Жыр | D6: Алпамыс батыр : эпостың баяны / ... – Астана : Фолиант, 2012. | E6: иә
A7: 6 | B7: Қобыланды батыр | C7: Жыр | D7: Қобыланды батыр [Мәтін] / ... – Алматы : Mazmundama, 2022 | E7: иә
A8: 7 | B8: Ер Тарғын | C8: Жыр | D8: Ер Тарғын [Мәтін] : батырлар жыры / ... – Астана : Алматыкітап, 2007. | E8: иә
A9: 8 | B9: Қамбар батыр | C9: Жыр | D9: https://bilim-all.kz/olen/4898-qambar-batyr | E9: иә
A10: 9 | B10: Қыз Жібек | C10: Жыр | D10: Қыз Жібек [Мәтін] : Лиро-эпостық поэма – Алматы : Мектеп, 2003. | E10: иә
A11: 10 | B11: Қозы Көрпеш – Баян сұлу | C11: Жыр | D11: Қозы Көрпеш - Баян Сұлу [Мәтін] : лиро-эпостық поэма : М. Ж. Көпейұлы нұсқасы / ... – Алматы : Мектеп, 2006 | E11: иә
A12: 11 | B12: Айман – Шолпан | C12: Жыр | D12: Айман-Шолпан [Мәтін] : Қазақ эпосы / ; Қазақ ССР Ғылым Академиясы, Тіл және әдебиет институты ; [баспаға даярлаған Ы. Т. Дүйсенбаев]... – Алматы : Қазақ ССР Ғылым Академиясының Баспасы, 1957 | E12: иә
D14: кітаптар https://kazneb.kz/ сайтынан оқылды

Sheet Мәтін талдауы
A1: № | B1: Шығарма | C1: Жанры | D1: Ойын | E1: Басқа ойын атауы | F1: Ойын түрі | G1: Кейіпкер | H1: Эпизод (өз сөзіңізбен) | I1: Қызметі (код) | J1: Дәйексөз (қысқа үзінді)
A2: 1 | B2: Алпамыс батыр | C2: =IFERROR(VLOOKUP(B2,Шығармалар!$B$2:$C$12,2,0),"") -> Жыр | D2: Жамбы ату | F2: =IFERROR(VLOOKUP(D2,Ойындар!$B$2:$C$14,2,0),"") -> Күш және мергендік ойындары | H2: Алпамыс бөгелген жоқ, садақты шірене тартып, жамбыны сыңғыр еткізіп атып түсірді. | I2: С | J2: Ұлтан ханға барсам деп, Жамбыны атып алсам деп, Көңілі тасып, құлшынды. Анасымен көрісіп, Көздің жасын төгісіп, Енді атына мінеді, Жамбыға қарай жүреді. «Диуана да келді!»— деп, Мазақ қып Ұлтан күледі. Атайын деп оқталып, Төсіне садақ тіреді. Атып тастап жамбыны, Ұлтанға жетіп келеді.
A3: 2 | B3: Алпамыс батыр | C3: =IFERROR(VLOOKUP(B3,Шығармалар!$B$2:$C$12,2,0),"") -> Жыр | D3: Көкпар | F3: =IFERROR(VLOOKUP(D3,Ойындар!$B$2:$C$14,2,0),"") -> Ат ойындары | H3: Жәдігер ойлады: «Менің көкпар шабатын заманым болса, өстіп жүрем бе, бұл көкпарды Қарлығаш апама апарып берейін, жігіттерге асып берсін!» — деп, мойнында кісен, аяғында шынжыр, құнан атына сүйретіп ауылға алып барды. | I3: Қ | J3: Гүлбаршынның алдына Көкпар әкеп тастады, Өңгеріп серке даладан.
A4: 3 | B4: Қобыланды батыр | C4: =IFERROR(VLOOKUP(B4,Шығармалар!$B$2:$C$12,2,0),"") -> Жыр | D4: Бәйге | F4: =IFERROR(VLOOKUP(D4,Ойындар!$B$2:$C$14,2,0),"") -> Ат ойындары | I4: Қ | J4: Бәйгеден келген кѳк дѳнен, Түнімен ұйқы кѳрмеген Қобландыдай батырдың Тоқтамасын білген соң, Тайбурылдың үстіне Алтыннан тұрман ер салып, Аз ғана азық, жем салып, Ақ орданың алдынан Ѳткізді Құртқа кѳлденең
A5: 4 | B5: Ер Төстік | C5: =IFERROR(VLOOKUP(B5,Шығармалар!$B$2:$C$12,2,0),"") -> Ертегі | D5: Бәйге | F5: =IFERROR(VLOOKUP(D5,Ойындар!$B$2:$C$14,2,0),"") -> Ат ойындары | I5: Қ | J5: Бұдан жеңілген соң Темір хан ат шабысына шығады. Өзінің бар жүйрігін бәйгеге қосады. Ер Төстік Шалқұйрықты даярлайды. Қарақшының түбіне келген соң, Шалқұйрыққа тіл бітеді: - Егер атты өте алысқа айдаса, менің шабысым өте жылдам болады. Үш күн шапсам, бүйірім қызып, өзімді тоқтатуға шамам келмей, кетіп қалуым мүмкін. Мен келе жатқанда алдымнан арқан керіп қой. Арқан үш қабат болсын, бір қабаты кендірден болсын. Үш қабат арқанның үшеуі де үзілсе, мен саған жоқпын, ағынымды тоқтата алмай кеткенім, үшеуі де үзілмесе, мен жығылып өлемін, онда да саған жоқпын. Егер арқан жартылай үзілсе, мен тоқтаймын, жығылып қалсам да, жаным қайтадан кіреді, күдер үзбе, - дейді. "Ер Төстіктің жалғыз шолағы бір жерде зарығып өліп қалсын!" - деп, Темір хан атты бір жұмалық жерге айдатады.Бір жеті өткен соң, бәйге аттары қайтып оралады. Темір хан мен Кеще хан балуан және ат бәйгесінен жеңіліп, не қыларын білмей, сасады. "Енді жаяу жарыс салып көрейік", - дейді.
A6: 5 | B6: Ер Төстік | C6: =IFERROR(VLOOKUP(B6,Шығармалар!$B$2:$C$12,2,0),"") -> Ертегі | D6: Күрес | F6: =IFERROR(VLOOKUP(D6,Ойындар!$B$2:$C$14,2,0),"") -> Күш және мергендік ойындары | I6: С | J6: Балуан күресі басталады. Таусоғарға балуан шақ келмейді. Жер астының алыптарының бәрі жығылып бітеді. Күресуге кісі шықпаған соң, Таусоғар бір тауды көтеріп алып, жұртқа күшін көрсетеді. Темір хан мен Кеще хан қатты сасып: -Тауды біз жаққа қоя көрмесін! - деп Төстікке жалынады.
A7: 6 | B7: Ер Төстік | C7: =IFERROR(VLOOKUP(B7,Шығармалар!$B$2:$C$12,2,0),"") -> Ертегі | D7: Асық | F7: =IFERROR(VLOOKUP(D7,Ойындар!$B$2:$C$14,2,0),"") -> Балалар ойындары | I7: Б | J7: Тағы бір күні Төстік асық ойнап жүріп, әлгі кемпірдің жалғыз баласын жұдырығымен қойып жіберсе, бала талып қалады.
A8: 7 | B8: Керқұла атты Кендебай | C8: =IFERROR(VLOOKUP(B8,Шығармалар!$B$2:$C$12,2,0),"") -> Ертегі | D8: Күрес | F8: =IFERROR(VLOOKUP(D8,Ойындар!$B$2:$C$14,2,0),"") -> Күш және мергендік ойындары | I8: Б | J8: Сондай күшті болыпты, алысқанын алып ұра беріпті, күрескенін жыға беріпті, шыңырау құдыққа құлаған атандарды жалғыз тартып шығара беріпті.
A9: 8 | B9: Алтын сақа | C9: =IFERROR(VLOOKUP(B9,Шығармалар!$B$2:$C$12,2,0),"") -> Ертегі | D9: Асық | F9: =IFERROR(VLOOKUP(D9,Ойындар!$B$2:$C$14,2,0),"") -> Балалар ойындары | I9: Б | J9: Сонымен бай жалмауыз кемпірге уәдесін беріп, жылқыларын айдап, кетіп қалады. Ертеңінде көшеді, жалғыз баласының алтын сақасын ұмыттырып, жұртқа тастап кетеді. Ауыл жаңа қонысқа көшіп барады. Асық ойнайын десе, сақасы жоқ, бала алтын сақасын жоқтап, жылайды. Жұртқа келсе, алтын сақасы ошақ басындағы тезек түбінде жатыр екен. Сақа жанында бір кемпір отыр екен. Бала кемпірге: — Шеше, анау жатқан сақамды алып берші! – дейді. Сонда кемпір: — Шырағым, өзің түсіп ал. Кәріліктен отырсам -тұра алмаймын, тұрсам - отыра алмаймын, – дейді.
A10: 9 | B10: Қыз Жібек | C10: =IFERROR(VLOOKUP(B10,Шығармалар!$B$2:$C$12,2,0),"") -> Жыр | D10: Асық | F10: =IFERROR(VLOOKUP(D10,Ойындар!$B$2:$C$14,2,0),"") -> Балалар ойындары | I10: Б | J10: Көп қызыққа батысқан, Тай құлындай тебіскен, Асық ойнап алысқан.
A11: 10 | B11: Күн астындағы Күнікей қыз | C11: =IFERROR(VLOOKUP(B11,Шығармалар!$B$2:$C$12,2,0),"") -> Ертегі | D11: Жаяу бәйге | F11: =IFERROR(VLOOKUP(D11,Ойындар!$B$2:$C$14,2,0),"") | I11: С | J11: Бірақ, хан сөзінен танып, бұл жолы қызын бермей: — Енді жаяу бәйгеден озып келгенге беремін, – дейді. Жаяу бәйгеге ханның елінен бір жүйрік мыстан кемпір шығады.
A12: 11 | B12: Күн астындағы Күнікей қыз | C12: =IFERROR(VLOOKUP(B12,Шығармалар!$B$2:$C$12,2,0),"") -> Ертегі | D12: Күрес | F12: =IFERROR(VLOOKUP(D12,Ойындар!$B$2:$C$14,2,0),"") -> Күш және мергендік ойындары | I12: С | J12: Хан ертеңіне, ел-жұртын жиып, балуан күрестіреді. Осы топта кімде-кім күресіп жығып, күші асса, қызымды соған беремін, – дейді. Ханның елі жағынан бір өгіз балуан шығады. Бала жағынан екі қолына екі тау ұстап жүруші дәу шығады. Екі балуан күресіп, дәу жығып кетеді.
A13: 12 | B13: Ер Тарғын | C13: =IFERROR(VLOOKUP(B13,Шығармалар!$B$2:$C$12,2,0),"") -> Жыр | D13: Бәйге | F13: =IFERROR(VLOOKUP(D13,Ойындар!$B$2:$C$14,2,0),"") -> Ат ойындары | I13: Қ | J13: Кебеже қарын, кең құрсақ, Құлжа мойын төгерек, Ұмтыла шапқан Тарланым, Алты мыңдай кісі екен, Тіл жіберсең саған серт! Сен желігіп жүргенде, Таяна шапса маған серт! Тауыса шапса бұ жауды, Сонда бітер Тарлан бәйгесі
A14: 13 | B14: Қамбар батыр | C14: =IFERROR(VLOOKUP(B14,Шығармалар!$B$2:$C$12,2,0),"") -> Жыр | D14: Аударыспақ | F14: =IFERROR(VLOOKUP(D14,Ойындар!$B$2:$C$14,2,0),"") -> Ат ойындары | I14: Қ | J14: Қараман шықты қаладан, Кернейлері бақылдап, Байрақтар тулап көтерген, Алтыннан қалқан жарқылдап, Сыбызғы, сырнай шақылдап, Мінгендері дәл бедеу, Келеді бектер дабылдап. Аударысып ойнайды Буыршындай тақымдап;
A15: 14 | B15: Қозы Көрпеш – Баян сұлу | C15: =IFERROR(VLOOKUP(B15,Шығармалар!$B$2:$C$12,2,0),"") -> Жыр | D15: Аударыспақ | F15: =IFERROR(VLOOKUP(D15,Ойындар!$B$2:$C$14,2,0),"") -> Ат ойындары | I15: Б | J15: Қарабай оны жақсы көріп, жылқы бағуға жұмсайды. Қозы алғашқыда Қодармен әзілдесіп, кейде ойнап, ат үстінен жұлып алып жүреді. Кейде тоқсан құлмен аударыспақ ойнап, оларды тегісімен топырлатып жүреді. Халық ақындары бұл жерде Қозы Көрпешті жойқын алып түрінде суреттеп, оның жеңбейтін адамы жоқ деп сипаттайды.
... A17: 16 | B17: Айман – Шолпан | C17: =IFERROR(VLOOKUP(B17,Шығармалар!$B$2:$C$12,2,0),"") -> Жыр | D17: Бәйге | F17: =IFERROR(VLOOKUP(D17,Ойындар!$B$2:$C$14,2,0),"") -> Ат ойындары | I17: Қ | J17: Басыбар: Тәйт, жоғал, ондайынды жолымнан ал былай! Күмілжімей, тек көмейің күлкілдемей сертінде қал жалтақтамай. Байлауым сол, кәзір бәйгеге ат жөнелтіп қайта мұнда келемін. Мыжымай қарсы алуға қамдана бер осы үйде!
A18: 17 | C18: =IFERROR(VLOOKUP(B18,Шығармалар!$B$2:$C$12,2,0),"") | F18: =IFERROR(VLOOKUP(D18,Ойындар!$B$2:$C$14,2,0),"")
A19: 18 | C19: =IFERROR(VLOOKUP(B19,Шығармалар!$B$2:$C$12,2,0),"") | F19: =IFERROR(VLOOKUP(D19,Ойындар!$B$2:$C$14,2,0),"")
A20: 19 | C20: =IFERROR(VLOOKUP(B20,Шығармалар!$B$2:$C$12,2,0),"") | F20: =IFERROR(VLOOKUP(D20,Ойындар!$B$2:$C$14,2,0),"")
A21: 20 | C21: =IFERROR(VLOOKUP(B21,Шығармалар!$B$2:$C$12,2,0),"") | F21: =IFERROR(VLOOKUP(D21,Ойындар!$B$2:$C$14,2,0),"")
A22: 21 | C22: =IFERROR(VLOOKUP(B22,Шығармалар!$B$2:$C$12,2,0),"") | F22: =IFERROR(VLOOKUP(D22,Ойындар!$B$2:$C$14,2,0),"")
A23: 22 | C23: =IFERROR(VLOOKUP(B23,Шығармалар!$B$2:$C$12,2,0),"") | F23: =IFERROR(VLOOKUP(D23,Ойындар!$B$2:$C$14,2,0),"")
A24: 23 | C24: =IFERROR(VLOOKUP(B24,Шығармалар!$B$2:$C$12,2,0),"") | F24: =IFERROR(VLOOKUP(D24,Ойындар!$B$2:$C$14,2,0),"")
A25: 24 | C25: =IFERROR(VLOOKUP(B25,Шығармалар!$B$2:$C$12,2,0),"") | F25: =IFERROR(VLOOKUP(D25,Ойындар!$B$2:$C$14,2,0),"")
A26: 25 | C26: =IFERROR(VLOOKUP(B26,Шығармалар!$B$2:$C$12,2,0),"") | F26: =IFERROR(VLOOKUP(D26,Ойындар!$B$2:$C$14,2,0),"")
A27: 26 | C27: =IFERROR(VLOOKUP(B27,Шығармалар!$B$2:$C$12,2,0),"") | F27: =IFERROR(VLOOKUP(D27,Ойындар!$B$2:$C$14,2,0),"")
A28: 27 | C28: =IFERROR(VLOOKUP(B28,Шығармалар!$B$2:$C$12,2,0),"") | F28: =IFERROR(VLOOKUP(D28,Ойындар!$B$2:$C$14,2,0),"")
A29: 28 | C29: =IFERROR(VLOOKUP(B29,Шығармалар!$B$2:$C$12,2,0),"") | F29: =IFERROR(VLOOKUP(D29,Ойындар!$B$2:$C$14,2,0),"")
... A81: 80 | C81: =IFERROR(VLOOKUP(B81,Шығармалар!$B$2:$C$12,2,0),"") | F81: =IFERROR(VLOOKUP(D81,Ойындар!$B$2:$C$14,2,0),"")

Sheet Сауалнама
A1: Код | B1: Сынып | C1: Бәйге: білу (0/1/2) | D1: Бәйге: ертегіден (1/0) | E1: Көкпар: білу (0/1/2) | F1: Көкпар: ертегіден (1/0) | G1: Қыз қуу: білу (0/1/2) | H1: Қыз қуу: ертегіден (1/0) | I1: Теңге алу: білу (0/1/2) | J1: Теңге алу: ертегіден (1/0) | K1: Аударыспақ: білу (0/1/2) | L1: Аударыспақ: ертегіден (1/0) | M1: Күрес: білу (0/1/2) | N1: Күрес: ертегіден (1/0) | O1: Жамбы ату: білу (0/1/2) | P1: Жамбы ату: ертегіден (1/0) | Q1: Тоғызқұмалақ: білу (0/1/2) | R1: Тоғызқұмалақ: ертегіден (1/0) | S1: Жұмбақ айтысу: білу (0/1/2) | T1: Жұмбақ айтысу: ертегіден (1/0) | U1: Асық: білу (0/1/2) | V1: Асық: ертегіден (1/0) | W1: Ақсүйек: білу (0/1/2) | X1: Ақсүйек: ертегіден (1/0) | Y1: Алтыбақан: білу (0/1/2) | Z1: Алтыбақан: ертегіден (1/0)
A2: С01
A3: С02
A4: С03
A5: С04
A6: С05
A7: С06
A8: С07
A9: С08
A10: С09
A11: С10
A12: С11
A13: С12
... A41: С40

Sheet Қорытынды
A1: Мәтін талдауы: ойындардың кездесуі
A2: Ойын | B2: Ертегіде | C2: Жырда | D2: Барлығы
A3: Бәйге | B3: =COUNTIFS('Мәтін талдауы'!$D$2:$D$81,A3,'Мәтін талдауы'!$C$2:$C$81,"Ертегі") -> 1 | C3: =COUNTIFS('Мәтін талдауы'!$D$2:$D$81,A3,'Мәтін талдауы'!$C$2:$C$81,"Жыр") -> 3 | D3: =B3+C3 -> 4
A4: Көкпар | B4: =COUNTIFS('Мәтін талдауы'!$D$2:$D$81,A4,'Мәтін талдауы'!$C$2:$C$81,"Ертегі") -> 0 | C4: =COUNTIFS('Мәтін талдауы'!$D$2:$D$81,A4,'Мәтін талдауы'!$C$2:$C$81,"Жыр") -> 1 | D4: =B4+C4 -> 1
A5: Қыз қуу | B5: =COUNTIFS('Мәтін талдауы'!$D$2:$D$81,A5,'Мәтін талдауы'!$C$2:$C$81,"Ертегі") -> 0 | C5: =COUNTIFS('Мәтін талдауы'!$D$2:$D$81,A5,'Мәтін талдауы'!$C$2:$C$81,"Жыр") -> 0 | D5: =B5+C5 -> 0
A6: Теңге алу | B6: =COUNTIFS('Мәтін талдауы'!$D$2:$D$81,A6,'Мәтін талдауы'!$C$2:$C$81,"Ертегі") -> 0 | C6: =COUNTIFS('Мәтін талдауы'!$D$2:$D$81,A6,'Мәтін талдауы'!$C$2:$C$81,"Жыр") -> 0 | D6: =B6+C6 -> 0
A7: Аударыспақ | B7: =COUNTIFS('Мәтін талдауы'!$D$2:$D$81,A7,'Мәтін талдауы'!$C$2:$C$81,"Ертегі") -> 0 | C7: =COUNTIFS('Мәтін талдауы'!$D$2:$D$81,A7,'Мәтін талдауы'!$C$2:$C$81,"Жыр") -> 2 | D7: =B7+C7 -> 2
A8: Күрес | B8: =COUNTIFS('Мәтін талдауы'!$D$2:$D$81,A8,'Мәтін талдауы'!$C$2:$C$81,"Ертегі") -> 3 | C8: =COUNTIFS('Мәтін талдауы'!$D$2:$D$81,A8,'Мәтін талдауы'!$C$2:$C$81,"Жыр") -> 0 | D8: =B8+C8 -> 3
A9: Жамбы ату | B9: =COUNTIFS('Мәтін талдауы'!$D$2:$D$81,A9,'Мәтін талдауы'!$C$2:$C$81,"Ертегі") -> 0 | C9: =COUNTIFS('Мәтін талдауы'!$D$2:$D$81,A9,'Мәтін талдауы'!$C$2:$C$81,"Жыр") -> 1 | D9: =B9+C9 -> 1
A10: Тоғызқұмалақ | B10: =COUNTIFS('Мәтін талдауы'!$D$2:$D$81,A10,'Мәтін талдауы'!$C$2:$C$81,"Ертегі") -> 0 | C10: =COUNTIFS('Мәтін талдауы'!$D$2:$D$81,A10,'Мәтін талдауы'!$C$2:$C$81,"Жыр") -> 0 | D10: =B10+C10 -> 0
A11: Жұмбақ айтысу | B11: =COUNTIFS('Мәтін талдауы'!$D$2:$D$81,A11,'Мәтін талдауы'!$C$2:$C$81,"Ертегі") -> 0 | C11: =COUNTIFS('Мәтін талдауы'!$D$2:$D$81,A11,'Мәтін талдауы'!$C$2:$C$81,"Жыр") -> 0 | D11: =B11+C11 -> 0
A12: Асық | B12: =COUNTIFS('Мәтін талдауы'!$D$2:$D$81,A12,'Мәтін талдауы'!$C$2:$C$81,"Ертегі") -> 2 | C12: =COUNTIFS('Мәтін талдауы'!$D$2:$D$81,A12,'Мәтін талдауы'!$C$2:$C$81,"Жыр") -> 2 | D12: =B12+C12 -> 4
A13: Ақсүйек | B13: =COUNTIFS('Мәтін талдауы'!$D$2:$D$81,A13,'Мәтін талдауы'!$C$2:$C$81,"Ертегі") -> 0 | C13: =COUNTIFS('Мәтін талдауы'!$D$2:$D$81,A13,'Мәтін талдауы'!$C$2:$C$81,"Жыр") -> 0 | D13: =B13+C13 -> 0
A14: Алтыбақан | B14: =COUNTIFS('Мәтін талдауы'!$D$2:$D$81,A14,'Мәтін талдауы'!$C$2:$C$81,"Ертегі") -> 0 | C14: =COUNTIFS('Мәтін талдауы'!$D$2:$D$81,A14,'Мәтін талдауы'!$C$2:$C$81,"Жыр") -> 0 | D14: =B14+C14 -> 0
A15: Басқа | B15: =COUNTIFS('Мәтін талдауы'!$D$2:$D$81,A15,'Мәтін талдауы'!$C$2:$C$81,"Ертегі") -> 0 | C15: =COUNTIFS('Мәтін талдауы'!$D$2:$D$81,A15,'Мәтін талдауы'!$C$2:$C$81,"Жыр") -> 0 | D15: =B15+C15 -> 0
A16: Барлық эпизод | B16: =SUM(B3:B15) -> 6 | C16: =SUM(C3:C15) -> 9 | D16: =SUM(D3:D15) -> 15
A18: Ойын түрлері
A19: Түрі | B19: Ертегіде | C19: Жырда | D19: Барлығы
A20: Ат ойындары | B20: =COUNTIFS('Мәтін талдауы'!$F$2:$F$81,A20,'Мәтін талдауы'!$C$2:$C$81,"Ертегі") -> 1 | C20: =COUNTIFS('Мәтін талдауы'!$F$2:$F$81,A20,'Мәтін талдауы'!$C$2:$C$81,"Жыр") -> 6 | D20: =B20+C20 -> 7
A21: Күш және мергендік ойындары | B21: =COUNTIFS('Мәтін талдауы'!$F$2:$F$81,A21,'Мәтін талдауы'!$C$2:$C$81,"Ертегі") -> 3 | C21: =COUNTIFS('Мәтін талдауы'!$F$2:$F$81,A21,'Мәтін талдауы'!$C$2:$C$81,"Жыр") -> 1 | D21: =B21+C21 -> 4
A22: Зияткерлік және сөз ойындары | B22: =COUNTIFS('Мәтін талдауы'!$F$2:$F$81,A22,'Мәтін талдауы'!$C$2:$C$81,"Ертегі") -> 0 | C22: =COUNTIFS('Мәтін талдауы'!$F$2:$F$81,A22,'Мәтін талдауы'!$C$2:$C$81,"Жыр") -> 0 | D22: =B22+C22 -> 0
A23: Балалар ойындары | B23: =COUNTIFS('Мәтін талдауы'!$F$2:$F$81,A23,'Мәтін талдауы'!$C$2:$C$81,"Ертегі") -> 2 | C23: =COUNTIFS('Мәтін талдауы'!$F$2:$F$81,A23,'Мәтін талдауы'!$C$2:$C$81,"Жыр") -> 2 | D23: =B23+C23 -> 4
A24: Ойын-сауық | B24: =COUNTIFS('Мәтін талдауы'!$F$2:$F$81,A24,'Мәтін талдауы'!$C$2:$C$81,"Ертегі") -> 0 | C24: =COUNTIFS('Мәтін талдауы'!$F$2:$F$81,A24,'Мәтін талдауы'!$C$2:$C$81,"Жыр") -> 0 | D24: =B24+C24 -> 0
A26: Ойынның сюжеттегі қызметі
A27: Қызметі | B27: Ертегіде | C27: Жырда | D27: Барлығы
A28: С – Сынақ | B28: =COUNTIFS('Мәтін талдауы'!$I$2:$I$81,"С",'Мәтін талдауы'!$C$2:$C$81,"Ертегі") -> 3 | C28: =COUNTIFS('Мәтін талдауы'!$I$2:$I$81,"С",'Мәтін талдауы'!$C$2:$C$81,"Жыр") -> 1 | D28: =B28+C28 -> 4
A29: Б – Сюжетті бастау | B29: =COUNTIFS('Мәтін талдауы'!$I$2:$I$81,"Б",'Мәтін талдауы'!$C$2:$C$81,"Ертегі") -> 3 | C29: =COUNTIFS('Мәтін талдауы'!$I$2:$I$81,"Б",'Мәтін талдауы'!$C$2:$C$81,"Жыр") -> 3 | D29: =B29+C29 -> 6
A30: Қ – Қасиетін көрсету | B30: =COUNTIFS('Мәтін талдауы'!$I$2:$I$81,"Қ",'Мәтін талдауы'!$C$2:$C$81,"Ертегі") -> 1 | C30: =COUNTIFS('Мәтін талдауы'!$I$2:$I$81,"Қ",'Мәтін талдауы'!$C$2:$C$81,"Жыр") -> 5 | D30: =B30+C30 -> 6
A31: Т – Той-думан көрінісі | B31: =COUNTIFS('Мәтін талдауы'!$I$2:$I$81,"Т",'Мәтін талдауы'!$C$2:$C$81,"Ертегі") -> 0 | C31: =COUNTIFS('Мәтін талдауы'!$I$2:$I$81,"Т",'Мәтін талдауы'!$C$2:$C$81,"Жыр") -> 0 | D31: =B31+C31 -> 0
A32: Ш – Шешуші сәт | B32: =COUNTIFS('Мәтін талдауы'!$I$2:$I$81,"Ш",'Мәтін талдауы'!$C$2:$C$81,"Ертегі") -> 0 | C32: =COUNTIFS('Мәтін талдауы'!$I$2:$I$81,"Ш",'Мәтін талдауы'!$C$2:$C$81,"Жыр") -> 0 | D32: =B32+C32 -> 0
A34: Сауалнама: қатысушылар саны | B34: =COUNTA(Сауалнама!$B$2:$B$41) -> 0
A35: Ойын | B35: Біледі, % | C35: Ойнаған, % | D35: Ертегіден оқыған, %
A36: Бәйге | B36: =IFERROR(ROUND(COUNTIF(Сауалнама!$C$2:$C$41,">=1")/COUNT(Сауалнама!$C$2:$C$41)*100,1),"") | C36: =IFERROR(ROUND(COUNTIF(Сауалнама!$C$2:$C$41,2)/COUNT(Сауалнама!$C$2:$C$41)*100,1),"") | D36: =IFERROR(ROUND(COUNTIF(Сауалнама!$D$2:$D$41,1)/COUNT(Сауалнама!$D$2:$D$41)*100,1),"")
A37: Көкпар | B37: =IFERROR(ROUND(COUNTIF(Сауалнама!$E$2:$E$41,">=1")/COUNT(Сауалнама!$E$2:$E$41)*100,1),"") | C37: =IFERROR(ROUND(COUNTIF(Сауалнама!$E$2:$E$41,2)/COUNT(Сауалнама!$E$2:$E$41)*100,1),"") | D37: =IFERROR(ROUND(COUNTIF(Сауалнама!$F$2:$F$41,1)/COUNT(Сауалнама!$F$2:$F$41)*100,1),"")
A38: Қыз қуу | B38: =IFERROR(ROUND(COUNTIF(Сауалнама!$G$2:$G$41,">=1")/COUNT(Сауалнама!$G$2:$G$41)*100,1),"") | C38: =IFERROR(ROUND(COUNTIF(Сауалнама!$G$2:$G$41,2)/COUNT(Сауалнама!$G$2:$G$41)*100,1),"") | D38: =IFERROR(ROUND(COUNTIF(Сауалнама!$H$2:$H$41,1)/COUNT(Сауалнама!$H$2:$H$41)*100,1),"")
A39: Теңге алу | B39: =IFERROR(ROUND(COUNTIF(Сауалнама!$I$2:$I$41,">=1")/COUNT(Сауалнама!$I$2:$I$41)*100,1),"") | C39: =IFERROR(ROUND(COUNTIF(Сауалнама!$I$2:$I$41,2)/COUNT(Сауалнама!$I$2:$I$41)*100,1),"") | D39: =IFERROR(ROUND(COUNTIF(Сауалнама!$J$2:$J$41,1)/COUNT(Сауалнама!$J$2:$J$41)*100,1),"")
A40: Аударыспақ | B40: =IFERROR(ROUND(COUNTIF(Сауалнама!$K$2:$K$41,">=1")/COUNT(Сауалнама!$K$2:$K$41)*100,1),"") | C40: =IFERROR(ROUND(COUNTIF(Сауалнама!$K$2:$K$41,2)/COUNT(Сауалнама!$K$2:$K$41)*100,1),"") | D40: =IFERROR(ROUND(COUNTIF(Сауалнама!$L$2:$L$41,1)/COUNT(Сауалнама!$L$2:$L$41)*100,1),"")
A41: Күрес | B41: =IFERROR(ROUND(COUNTIF(Сауалнама!$M$2:$M$41,">=1")/COUNT(Сауалнама!$M$2:$M$41)*100,1),"") | C41: =IFERROR(ROUND(COUNTIF(Сауалнама!$M$2:$M$41,2)/COUNT(Сауалнама!$M$2:$M$41)*100,1),"") | D41: =IFERROR(ROUND(COUNTIF(Сауалнама!$N$2:$N$41,1)/COUNT(Сауалнама!$N$2:$N$41)*100,1),"")
A42: Жамбы ату | B42: =IFERROR(ROUND(COUNTIF(Сауалнама!$O$2:$O$41,">=1")/COUNT(Сауалнама!$O$2:$O$41)*100,1),"") | C42: =IFERROR(ROUND(COUNTIF(Сауалнама!$O$2:$O$41,2)/COUNT(Сауалнама!$O$2:$O$41)*100,1),"") | D42: =IFERROR(ROUND(COUNTIF(Сауалнама!$P$2:$P$41,1)/COUNT(Сауалнама!$P$2:$P$41)*100,1),"")
A43: Тоғызқұмалақ | B43: =IFERROR(ROUND(COUNTIF(Сауалнама!$Q$2:$Q$41,">=1")/COUNT(Сауалнама!$Q$2:$Q$41)*100,1),"") | C43: =IFERROR(ROUND(COUNTIF(Сауалнама!$Q$2:$Q$41,2)/COUNT(Сауалнама!$Q$2:$Q$41)*100,1),"") | D43: =IFERROR(ROUND(COUNTIF(Сауалнама!$R$2:$R$41,1)/COUNT(Сауалнама!$R$2:$R$41)*100,1),"")
...
